<?xml version="1.0" ?>

<robot name="robot_arm">
  <material name="white">
    <color rgba="1.0 1.0 1.0 1.000"/>
  </material>

  <link name="world">
  </link>
  <joint name="base_joint" type="fixed">
    <origin xyz="0.0 0.0 0.0" rpy="0 0 0"/>
    <parent link="world"/>
    <child link="base_link"/>
  </joint>
  <link name="base_link">
    <inertial>
      <origin xyz="-1.1285154625619664e-16 0.000334248090355596 0.05270475953078982" rpy="0 0 0"/>
      <mass value="2.5305930297877364"/>
      <inertia ixx="0.004399" iyy="0.004429" izz="0.004405" ixy="-0.0" iyz="-3e-05" ixz="0.0"/>
    </inertial>
    <visual>
      <origin xyz="0 0 0" rpy="0 0 0"/>
      <geometry>
        <mesh filename="file:///home/wwd9861/robot_arm_ws/src/robot_arm_description/meshes/base_link.stl" scale="0.001 0.001 0.001"/>
      </geometry>
      <material name="white"/>
    </visual>
    <collision>
      <origin xyz="0 0 0" rpy="0 0 0"/>
      <geometry>
        <mesh filename="file:///home/wwd9861/robot_arm_ws/src/robot_arm_description/meshes/base_link.stl" scale="0.001 0.001 0.001"/>
      </geometry>
    </collision>
  </link>

  <link name="rotate">
    <inertial>
      <origin xyz="4.5802358023220294e-14 -5.433637081973642e-17 0.004960836668469221" rpy="0 0 0"/>
      <mass value="0.6631591419630531"/>
      <inertia ixx="0.000472" iyy="0.000472" izz="0.000933" ixy="-0.0" iyz="0.0" ixz="0.0"/>
    </inertial>
    <visual>
      <origin xyz="-0.0 0.0 -0.1116" rpy="0 0 0"/>
      <geometry>
        <mesh filename="file:///home/wwd9861/robot_arm_ws/src/robot_arm_description/meshes/rotate.stl" scale="0.001 0.001 0.001"/>
      </geometry>
      <material name="white"/>
    </visual>
    <collision>
      <origin xyz="-0.0 0.0 -0.1116" rpy="0 0 0"/>
      <geometry>
        <mesh filename="file:///home/wwd9861/robot_arm_ws/src/robot_arm_description/meshes/rotate.stl" scale="0.001 0.001 0.001"/>
      </geometry>
    </collision>
  </link>

  <link name="link_1">
    <inertial>
      <origin xyz="0.005073022662102248 1.1129625197867522e-16 0.030468242291165196" rpy="0 0 0"/>
      <mass value="0.7144960689551971"/>
      <inertia ixx="0.000504" iyy="0.000445" izz="0.000319" ixy="0.0" iyz="-0.0" ixz="-1.1e-05"/>
    </inertial>
    <visual>
      <origin xyz="0.0 0.0 -0.1216" rpy="0 0 0"/>
      <geometry>
        <mesh filename="file:///home/wwd9861/robot_arm_ws/src/robot_arm_description/meshes/link_1.stl" scale="0.001 0.001 0.001"/>
      </geometry>
      <material name="white"/>
    </visual>
    <collision>
      <origin xyz="0.0 0.0 -0.1216" rpy="0 0 0"/>
      <geometry>
        <mesh filename="file:///home/wwd9861/robot_arm_ws/src/robot_arm_description/meshes/link_1.stl" scale="0.001 0.001 0.001"/>
      </geometry>
    </collision>
  </link>

  <link name="link_2">
    <inertial>
      <origin xyz="-0.026722953125703622 0.00013326397239959964 0.06739644020751445" rpy="0 0 0"/>
      <mass value="1.0723019224070052"/>
      <inertia ixx="0.002051" iyy="0.001984" izz="0.000559" ixy="0.0" iyz="-3e-06" ixz="0.000178"/>
    </inertial>
    <visual>
      <origin xyz="0.025 0.0 -0.1666" rpy="0 0 0"/>
      <geometry>
        <mesh filename="file:///home/wwd9861/robot_arm_ws/src/robot_arm_description/meshes/link_2.stl" scale="0.001 0.001 0.001"/>
      </geometry>
      <material name="white"/>
    </visual>
    <collision>
      <origin xyz="0.025 0.0 -0.1666" rpy="0 0 0"/>
      <geometry>
        <mesh filename="file:///home/wwd9861/robot_arm_ws/src/robot_arm_description/meshes/link_2.stl" scale="0.001 0.001 0.001"/>
      </geometry>
    </collision>
  </link>

  <link name="link_3">
    <inertial>
      <origin xyz="0.02672295312570343 -0.0001332639723983275 0.06739644020751456" rpy="0 0 0"/>
      <mass value="1.0723019224070065"/>
      <inertia ixx="0.002051" iyy="0.001984" izz="0.000559" ixy="0.0" iyz="3e-06" ixz="-0.000178"/>
    </inertial>
    <visual>
      <origin xyz="0.025 -0.0002 -0.2716" rpy="0 0 0"/>
      <geometry>
        <mesh filename="file:///home/wwd9861/robot_arm_ws/src/robot_arm_description/meshes/link_3.stl" scale="0.001 0.001 0.001"/>
      </geometry>
      <material name="white"/>
    </visual>
    <collision>
      <origin xyz="0.025 -0.0002 -0.2716" rpy="0 0 0"/>
      <geometry>
        <mesh filename="file:///home/wwd9861/robot_arm_ws/src/robot_arm_description/meshes/link_3.stl" scale="0.001 0.001 0.001"/>
      </geometry>
    </collision>
  </link>

  <link name="link_4">
    <inertial>
      <origin xyz="-0.022138072415002215 2.5575291463440436e-15 0.008752607826837788" rpy="0 0 0"/>
      <mass value="0.28036972878940647"/>
      <inertia ixx="0.000201" iyy="0.000191" izz="0.000152" ixy="-0.0" iyz="0.0" ixz="7e-06"/>
    </inertial>
    <visual>
      <origin xyz="0.025 -0.0 -0.3766" rpy="0 0 0"/>
      <geometry>
        <mesh filename="file:///home/wwd9861/robot_arm_ws/src/robot_arm_description/meshes/link_4.stl" scale="0.001 0.001 0.001"/>
      </geometry>
      <material name="white"/>
    </visual>
    <collision>
      <origin xyz="0.025 -0.0 -0.3766" rpy="0 0 0"/>
      <geometry>
        <mesh filename="file:///home/wwd9861/robot_arm_ws/src/robot_arm_description/meshes/link_4.stl" scale="0.001 0.001 0.001"/>
      </geometry>
    </collision>
  </link>


  <joint name="revolute1" type="revolute">
    <origin xyz="0.0 0.0 0.1116" rpy="0 0 0"/>
    <parent link="base_link"/>
    <child link="rotate"/>
    <axis xyz="0.0 0.0 1.0"/>
    <limit effort="10" lower="-3.141592" upper="3.141592" velocity="20.0" />
    <dynamics damping="0.0" friction="10.0"/>
  </joint>

  <joint name="fixed1" type="fixed">
    <origin xyz="-0.0 0.0 0.01" rpy="0 0 0"/>
    <parent link="rotate"/>
    <child link="link_1"/>
  </joint>

  <joint name="revolute2" type="revolute">
    <origin xyz="-0.025 0.0 0.045" rpy="0 0 0"/>
    <parent link="link_1"/>
    <child link="link_2"/>
    <axis xyz="-1.0 0.0 0.0"/>
    <limit effort="10" lower="-3.141592" upper="3.141592" velocity="20.0" />
    <dynamics damping="0.0" friction="10.0"/>
  </joint>

  <joint name="revolute3" type="revolute">
    <origin xyz="0.0 0.0002 0.105" rpy="0 0 0"/>
    <parent link="link_2"/>
    <child link="link_3"/>
    <axis xyz="-1.0 -0.0 0.0"/>
    <limit effort="10" lower="-3.141592" upper="3.141592" velocity="20.0" />
    <dynamics damping="0.0" friction="10.0"/>
  </joint>

  <joint name="revolute4" type="revolute">
    <origin xyz="0.0 -0.0002 0.105" rpy="0 0 0"/>
    <parent link="link_3"/>
    <child link="link_4"/>
    <axis xyz="-1.0 0.0 0.0"/>
    <limit effort="10" lower="-3.141592" upper="3.141592" velocity="20.0" />
    <dynamics damping="0.0" friction="10.0"/>
  </joint>

  <gazebo reference="base_link">
    <material>Gazebo/Blue</material>
    <selfCollide>true</selfCollide>
  </gazebo>
  <gazebo reference="link_1">
    <material>Gazebo/White</material>
    <selfCollide>true</selfCollide>
  </gazebo>
  <gazebo reference="link_2">
    <material>Gazebo/White</material>
    <selfCollide>true</selfCollide>
  </gazebo>
  <gazebo reference="link_3">
    <material>Gazebo/White</material>
    <selfCollide>true</selfCollide>
  </gazebo>
  <gazebo reference="link_4">
    <material>Gazebo/White</material>
    <selfCollide>true</selfCollide>
  </gazebo>
  <gazebo reference="rotate">
    <material>Gazebo/Blue</material>
    <selfCollide>true</selfCollide>
  </gazebo>

  <ros2_control name="GazeboSystem" type="system">
    <hardware>
      <plugin>gazebo_ros2_control/GazeboSystem</plugin>
    </hardware>
    <joint name="revolute1">
      <command_interface name="position">
      </command_interface>
      <state_interface name="position">
        <param name="initial_value">0</param>
      </state_interface>
      <state_interface name="velocity"/>
    </joint>
    
    <joint name="revolute2">
      <command_interface name="position">
      </command_interface>
      <state_interface name="position">
        <param name="initial_value">0</param>
      </state_interface>
      <state_interface name="velocity"/>
    </joint>

    <joint name="revolute3">
      <command_interface name="position">
      </command_interface>
      <state_interface name="position">
        <param name="initial_value">0</param>
      </state_interface>
      <state_interface name="velocity"/>
    </joint>

    <joint name="revolute4">
      <command_interface name="position">
      </command_interface>
      <state_interface name="position">
        <param name="initial_value">0</param>
      </state_interface>
      <state_interface name="velocity"/>
    </joint>

  </ros2_control>

  <gazebo>
    <plugin filename="libgazebo_ros2_control.so" name="gazebo_ros2_control">
      <parameters>$(find robot_arm_description)/config/joint_controller.yaml</parameters>
    </plugin>
  </gazebo>

</robot>
